Workbook

Sheet regression-result-2
A1: SUMMARY OUTPUT
A3: Regression Statistics
A4: Multiple R | B4: 0.68224766
A5: R Square | B5: 0.46546187
A6: Adjusted R Square | B6: 0.41406397
A7: Standard Error | B7: 1.7996766
A8: Observations | B8: 58
A10: ANOVA
B11: df | C11: SS | D11: MS | E11: F | F11: Significance F
A12: Regression | B12: 5 | C12: 146.65529 | D12: 29.331058 | E12: 9.056049 | F12: 3.0621314e-06
A13: Residual | B13: 52 | C13: 168.41947 | D13: 3.238836
A14: Total | B14: 57 | C14: 315.07476
B16: Coefficients | C16: Standard Error | D16: t Stat | E16: P-value | F16: Lower 95% | G16: Upper 95% | H16: Lower 95.0% | I16: Upper 95.0%
A17: Intercept | B17: -0.22132543 | C17: 1.1160959 | D17: -0.19830323 | E17: 0.84358107 | F17: -2.4609358 | G17: 2.0182849 | H17: -2.4609358 | I17: 2.0182849
A18: Area | B18: 0.0088655074 | C18: 0.0049051893 | D18: 1.8073732 | E18: 0.076490391 | F18: -0.00097747495 | G18: 0.01870849 | H18: -0.00097747495 | I18: 0.01870849
A19: Access Road | B19: 0.046657473 | C19: 0.038647174 | D19: 1.2072674 | E19: 0.2327921 | F19: -0.030893755 | G19: 0.1242087 | H19: -0.030893755 | I19: 0.1242087
A20: Floors | B20: 0.33350321 | C20: 0.2394135 | D20: 1.3930008 | E20: 0.16954649 | F20: -0.14691513 | G20: 0.81392155 | H20: -0.14691513 | I20: 0.81392155
A21: Bedrooms | B21: 0.52487559 | C21: 0.23858345 | D21: 2.1999665 | E21: 0.032276761 | F21: 0.046122882 | G21: 1.0036283 | H21: 0.046122882 | I21: 1.0036283
A22: Bathrooms | B22: 0.49542351 | C22: 0.29639289 | D22: 1.6715094 | E22: 0.10062922 | F22: -0.099332345 | G22: 1.0901794 | H22: -0.099332345 | I22: 1.0901794
A26: RESIDUAL OUTPUT
A28: Observation | B28: Predicted Price | C28: Residuals | D28: Standard Residuals
A29: 1 | B29: 9.5673996 | C29: -0.16739964 | D29: -0.097385839
A30: 2 | B30: 6.3770655 | C30: 1.6129345 | D30: 0.93833519
A31: 3 | B31: 6.8372699 | C31: -1.2372699 | D31: -0.71978986
A32: 4 | B32: 8.3581393 | C32: -2.0581393 | D32: -1.197336
A33: 5 | B33: 8.5325388 | C33: 0.097461245 | D33: 0.056698717
A34: 6 | B34: 7.8531918 | C34: 0.94680815 | D34: 0.55081184
A35: 7 | B35: 5.4616421 | C35: 0.13835787 | D35: 0.080490595
A36: 8 | B36: 6.8022445 | C36: -0.30224454 | D36: -0.17583274
A37: 9 | B37: 5.6500903 | C37: -2.4500903 | D37: -1.4253561
A38: 10 | B38: 5.3883881 | C38: -0.90838814 | D38: -0.52846074
A39: 11 | B39: 5.2858424 | C39: 1.4941576 | D39: 0.86923599
A40: 12 | B40: 8.8473465 | C40: 0.85265354 | D40: 0.49603678
... A71: 43 | B71: 9.7866382 | C71: 0.21336179 | D71: 0.12412462
A72: 44 | B72: 5.931113 | C72: 3.868887 | D72: 2.2507503 | E72: >2*sigma | F72: loai di mo hinh se tot hon
A73: 45 | B73: 5.8567917 | C73: 1.6432083 | D73: 0.9559472
A74: 46 | B74: 5.4084491 | C74: -2.2084491 | D74: -1.2847797
A75: 47 | B75: 5.921316 | C75: -1.921316 | D75: -1.1177381
A76: 48 | B76: 8.0422181 | C76: 0.55778187 | D76: 0.32449325
A77: 49 | B77: 5.0302418 | C77: 3.4697582 | D77: 2.0185545 | E77: >2*sigma
...

Sheet data (2)
D1: -0.060916211 | E1: 0.0067290086 | F1: 0.043076757 | G1: 0.26646991 | H1: 0.46030167 | I1: 0.57793096
A2: Province | B2: House direction | C2: Balcony direction | E2: Area | F2: Access Road | G2: Floors | H2: Bedrooms | I2: Bathrooms | J2: Price
A3: Quảng Ninh | B3: Đông | C3: Nam | E3: 300 | F3: 32 | G3: 3 | H3: 6 | I3: 3 | J3: 9.4
A4: Hồ Chí Minh | B4: Đông - Nam | C4: Đông - Nam | E4: 46 | F4: 6 | G4: 4 | H4: 4 | I4: 5 | J4: 7.99
A5: Hồ Chí Minh | B5: Đông - Nam | C5: Đông | E5: 60 | F5: 5 | G5: 2 | H5: 6 | I5: 5 | J5: 5.6
A6: Phú Thọ | B6: Đông - Nam | C6: Đông - Nam | E6: 369 | F6: 12 | G6: 2 | H6: 4 | I6: 4 | J6: 6.3
A7: Hưng Yên | B7: Đông - Nam | C7: Đông - Nam | E7: 78 | F7: 13 | G7: 4 | H7: 6 | I7: 6 | J7: 8.63
A8: Hà Nội | B8: Tây - Bắc | C8: Tây - Bắc | E8: 54 | F8: 3 | G8: 4 | H8: 6 | I8: 6 | J8: 8.8
A9: Hà Nội | B9: Tây - Nam | C9: Tây - Nam | E9: 36 | F9: 3 | G9: 5 | H9: 3 | I9: 4 | J9: 5.6
A10: Hồ Chí Minh | B10: Bắc | C10: Bắc | E10: 100 | F10: 12 | G10: 3 | H10: 4 | I10: 5 | J10: 6.5
A11: Long An | B11: Tây | C11: Tây | E11: 151 | F11: 6 | G11: 2 | H11: 4 | I11: 3 | J11: 3.2
A12: Hà Nội | B12: Tây - Bắc | C12: Tây - Bắc | E12: 33 | F12: 2 | G12: 5 | H12: 3 | I12: 4 | J12: 4.48
A13: Hồ Chí Minh | B13: Đông - Bắc | C13: Đông - Bắc | E13: 38 | F13: 6 | G13: 4 | H13: 3 | I13: 4 | J13: 6.78
A14: Bắc Ninh | B14: Nam | C14: Nam | E14: 180 | F14: 40 | G14: 3 | H14: 5 | I14: 4 | J14: 9.7
... A60: Hà Nội | B60: Tây - Bắc | C60: Tây - Bắc | E60: 53 | F60: 7 | G60: 5 | H60: 8 | I60: 5 | J60: 8.8

Sheet regression-result
A1: SUMMARY OUTPUT | D1: http://ceb.net.vn/ML/score.html
A3: Regression Statistics
A4: Multiple R | B4: 0.65140169 | D4: =SQRT(B5) -> 0.65140169
A5: R Square | B5: 0.42432416
A6: Adjusted R Square | B6: 0.35790002
A7: Standard Error | B7: 1.9107481 | C7: coi phan Residuals cái nào > 2 hoặc 3 SE thì nó là outliner
A8: Observations | B8: 59 | C8: số quan sát
B9: bậc tự do | E9: de tra tra bảng F | F9: P-value hết hết mô hình
A10: ANOVA
B11: df | C11: SS | D11: MS | E11: F | F11: Significance F
A12: Regression (k) | B12: 6 | C12: 139.93617 | D12: 23.322695 | E12: 6.3881021 | F12: 4.3754329e-05
A13: Residual (n-k-1) | B13: 52 | C13: 189.84984 | D13: 3.6509584
A14: Total | B14: 58 | C14: 329.78601
E15: Kiem dinh H0: betai = 0
B16: Coefficients | C16: Standard Error | D16: t Stat | E16: P-value | F16: Lower 95% | G16: Upper 95% | H16: Lower 95.0% | I16: Upper 95.0%
A17: Intercept | B17: -0.060916211 | C17: 1.2226928 | D17: -0.049821355 | E17: 0.96045563 | F17: -2.5144288 | G17: 2.3925964 | H17: -2.5144288 | I17: 2.3925964
A18: Area | B18: 0.0067290086 | C18: 0.0069191691 | D18: 0.97251685 | E18: 0.33529578 | F18: -0.00715532 | G18: 0.020613337 | H18: -0.00715532 | I18: 0.020613337
A19: Frontage | B19: 0.055462846 | C19: 0.12394651 | D19: 0.44747406 | E19: 0.65639135 | F19: -0.19325401 | G19: 0.3041797 | H19: -0.19325401 | I19: 0.3041797
A20: Access Road | B20: 0.043076757 | C20: 0.041143914 | D20: 1.0469776 | E20: 0.29995219 | F20: -0.039484546 | G20: 0.12563806 | H20: -0.039484546 | I20: 0.12563806
A21: Floors | B21: 0.26646991 | C21: 0.25272117 | D21: 1.0544028 | E21: 0.2965732 | F21: -0.24065222 | G21: 0.77359205 | H21: -0.24065222 | I21: 0.77359205
A22: Bedrooms | B22: 0.46030167 | C22: 0.25617748 | D22: 1.7968077 | E22: 0.078175168 | F22: -0.053756052 | G22: 0.97435939 | H22: -0.053756052 | I22: 0.97435939
A23: Bathrooms | B23: 0.57793096 | C23: 0.31884488 | D23: 1.8125772 | E23: 0.075671812 | F23: -0.0618781 | G23: 1.21774 | H23: -0.0618781 | I23: 1.21774
E25: =MAX(E18:E23) -> 0.65639135
J26: {=cor} -> #NAME?
A27: RESIDUAL OUTPUT | F27: PROBABILITY OUTPUT
A29: Observation | B29: Predicted Price | C29: Residuals | D29: Standard Residuals | E29: =AVERAGE(C30:C88) -> -1.3172138e-15 | F29: Percentile | G29: Price
A30: 1 | B30: 9.4631979 | C30: -0.063197936 | D30: -0.034931061 | E30: =(C30-$E$29)/$B$7 -> -0.033074969 | F30: 0.84745763 | G30: 2.1
A31: 2 | B31: 6.558949 | C31: 1.431051 | D31: 0.79097727 | E31: =(C31-$E$29)/$B$7 -> 0.74894802 | F31: 2.5423729 | G31: 2.16
A32: 3 | B32: 6.9367327 | C32: -1.3367327 | D32: -0.7388452 | E32: =(C32-$E$29)/$B$7 -> -0.69958603 | F32: 4.2372881 | G32: 2.25
A33: 4 | B33: 8.4568221 | C33: -2.1568221 | D33: -1.1921289 | E33: =(C33-$E$29)/$B$7 -> -1.1287841 | F33: 5.9322034 | G33: 2.4
A34: 5 | B34: 8.6519968 | C34: -0.021996826 | D34: -0.012158189 | E34: =(C34-$E$29)/$B$7 -> -0.011512153 | F34: 7.6271186 | G34: 2.65
A35: 6 | B35: 8.0486405 | C35: 0.75135952 | D35: 0.41529497 | E35: =(C35-$E$29)/$B$7 -> 0.39322792 | F35: 9.3220339 | G35: 2.65
A36: 7 | B36: 5.3117937 | C36: 4.6882063 | D36: 2.5912875 | E36: =(C36-$E$29)/$B$7 -> 2.4535972 | F36: 11.016949 | G36: 2.75
A37: 8 | B37: 5.7237767 | C37: -0.12377672 | D37: -0.068414452 | E37: =(C37-$E$29)/$B$7 -> -0.064779192 | F37: 12.711864 | G37: 3
A38: 9 | B38: 7.7684339 | C38: -1.2684339 | D38: -0.70109475 | E38: =(C38-$E$29)/$B$7 -> -0.66384149 | F38: 14.40678 | G38: 3.2
A39: 10 | B39: 5.5434154 | C39: -2.3434154 | D39: -1.2952636 | E39: =(C39-$E$29)/$B$7 -> -1.2264387 | F39: 16.101695 | G39: 3.2
A40: 11 | B40: 5.4386616 | C40: -0.95866155 | D40: -0.52987593 | E40: =(C40-$E$29)/$B$7 -> -0.50172052 | F40: 17.79661 | G40: 3.25
A41: 12 | B41: 5.4446991 | C41: 1.3353009 | D41: 0.73805379 | E41: =(C41-$E$29)/$B$7 -> 0.69883668 | F41: 19.491525 | G41: 3.95
... A88: 59 | B88: 8.6957962 | C88: 0.10420375 | D88: 0.05759599 | E88: =(C88-$E$29)/$B$7 -> 0.054535578 | F88: 99.152542 | G88: 10

Sheet data
D1: -0.060916211 | E1: 0.0067290086 | F1: 0.055462846 | G1: 0.043076757 | H1: 0.26646991 | I1: 0.46030167 | J1: 0.57793096 | L1: y mean = | M1: =AVERAGE(K3:K61) -> 6.1971186
A2: Province | B2: House direction | C2: Balcony direction | E2: Area | F2: Frontage | G2: Access Road | H2: Floors | I2: Bedrooms | J2: Bathrooms | K2: Price | L2: y predict | M2: Residuals | N2: |Residuals| | O2: |Residuals|/|y|
A3: Quảng Ninh | B3: Đông | C3: Nam | E3: 300 | F3: 15 | G3: 32 | H3: 3 | I3: 6 | J3: 3 | K3: 9.4 | L3: =D1+SUMPRODUCT($E$1:$J$1,E3:J3) -> 9.4631979 | M3: =K3-L3 -> -0.063197936 | N3: =ABS(M3) -> 0.063197936 | O3: =N3/ABS(K3) -> 0.0067231847 | P3: =POWER(M3,2) -> 0.0039939791 | Q3: =POWER(LOG10(1+K3)-LOG10(1+L3),2) -> 6.9226967e-06 | R3: =POWER(K3-$M$1,2) -> 10.258449 | S3: =ABS(K3-$M$1) -> 3.2028814
A4: Hồ Chí Minh | B4: Đông - Nam | C4: Đông - Nam | E4: 46 | F4: 4.6 | G4: 6 | H4: 4 | I4: 4 | J4: 5 | K4: 7.99 | L4: =D2+SUMPRODUCT($E$1:$J$1,E4:J4) -> 6.6198652 | M4: =K4-L4 -> 1.3701348 | N4: =ABS(M4) -> 1.3701348 | O4: =N4/ABS(K4) -> 0.1714812 | P4: =POWER(M4,2) -> 1.8772694 | Q4: =POWER(LOG10(1+K4)-LOG10(1+L4),2) -> 0.0051570215 | R4: =POWER(K4-$M$1,2) -> 3.2144236 | S4: =ABS(K4-$M$1) -> 1.7928814
A5: Hồ Chí Minh | B5: Đông - Nam | C5: Đông | E5: 60 | F5: 3.5 | G5: 5 | H5: 2 | I5: 6 | J5: 5 | K5: 5.6 | L5: =D3+SUMPRODUCT($E$1:$J$1,E5:J5) -> 6.9976489 | M5: =K5-L5 -> -1.3976489 | N5: =ABS(M5) -> 1.3976489 | O5: =N5/ABS(K5) -> 0.24958016 | P5: =POWER(M5,2) -> 1.9534225 | Q5: =POWER(LOG10(1+K5)-LOG10(1+L5),2) -> 0.0069586295 | R5: =POWER(K5-$M$1,2) -> 0.35655068 | S5: =ABS(K5-$M$1) -> 0.59711864
A6: Phú Thọ | B6: Đông - Nam | C6: Đông - Nam | E6: 369 | F6: 15 | G6: 12 | H6: 2 | I6: 4 | J6: 4 | K6: 6.3 | L6: =D4+SUMPRODUCT($E$1:$J$1,E6:J6) -> 8.5177383 | M6: =K6-L6 -> -2.2177383 | N6: =ABS(M6) -> 2.2177383 | O6: =N6/ABS(K6) -> 0.35202195 | P6: =POWER(M6,2) -> 4.9183631 | Q6: =POWER(LOG10(1+K6)-LOG10(1+L6),2) -> 0.013273551 | R6: =POWER(K6-$M$1,2) -> 0.010584573 | S6: =ABS(K6-$M$1) -> 0.10288136
A7: Hưng Yên | B7: Đông - Nam | C7: Đông - Nam | E7: 78 | F7: 6 | G7: 13 | H7: 4 | I7: 6 | J7: 6 | K7: 8.63 | L7: =D5+SUMPRODUCT($E$1:$J$1,E7:J7) -> 8.712913 | M7: =K7-L7 -> -0.082913036 | N7: =ABS(M7) -> 0.082913036 | O7: =N7/ABS(K7) -> 0.0096075361 | P7: =POWER(M7,2) -> 0.0068745716 | Q7: =POWER(LOG10(1+K7)-LOG10(1+L7),2) -> 1.3862317e-05 | R7: =POWER(K7-$M$1,2) -> 5.9189117 | S7: =ABS(K7-$M$1) -> 2.4328814
A8: Hà Nội | B8: Tây - Bắc | C8: Tây - Bắc | E8: 54 | F8: 5.8 | G8: 3 | H8: 4 | I8: 6 | J8: 6 | K8: 8.8 | L8: =D6+SUMPRODUCT($E$1:$J$1,E8:J8) -> 8.1095567 | M8: =K8-L8 -> 0.69044331 | N8: =ABS(M8) -> 0.69044331 | O8: =N8/ABS(K8) -> 0.078459467 | P8: =POWER(M8,2) -> 0.47671197 | Q8: =POWER(LOG10(1+K8)-LOG10(1+L8),2) -> 0.0010067188 | R8: =POWER(K8-$M$1,2) -> 6.7749914 | S8: =ABS(K8-$M$1) -> 2.6028814
A9: Hồ Chí Minh | B9: Đông - Bắc | C9: Đông - Bắc | E9: 69.1 | F9: 4 | G9: 4.5 | H9: 3 | I9: 3 | J9: 4 | K9: 10 | L9: =D7+SUMPRODUCT($E$1:$J$1,E9:J9) -> 5.3727099 | M9: =K9-L9 -> 4.6272901 | N9: =ABS(M9) -> 4.6272901 | O9: =N9/ABS(K9) -> 0.46272901 | P9: =POWER(M9,2) -> 21.411814 | Q9: =POWER(LOG10(1+K9)-LOG10(1+L9),2) -> 0.056201491 | R9: =POWER(K9-$M$1,2) -> 14.461907 | S9: =ABS(K9-$M$1) -> 3.8028814
A10: Hà Nội | B10: Tây - Nam | C10: Tây - Nam | E10: 36 | F10: 7 | G10: 3 | H10: 5 | I10: 3 | J10: 4 | K10: 5.6 | L10: =D8+SUMPRODUCT($E$1:$J$1,E10:J10) -> 5.7846929 | M10: =K10-L10 -> -0.18469293 | N10: =ABS(M10) -> 0.18469293 | O10: =N10/ABS(K10) -> 0.03298088 | P10: =POWER(M10,2) -> 0.034111479 | Q10: =POWER(LOG10(1+K10)-LOG10(1+L10),2) -> 0.00014367045 | R10: =POWER(K10-$M$1,2) -> 0.35655068 | S10: =ABS(K10-$M$1) -> 0.59711864
A11: Hồ Chí Minh | B11: Bắc | C11: Bắc | E11: 100 | F11: 20 | G11: 12 | H11: 3 | I11: 4 | J11: 5 | K11: 6.5 | L11: =D9+SUMPRODUCT($E$1:$J$1,E11:J11) -> 7.8293501 | M11: =K11-L11 -> -1.3293501 | N11: =ABS(M11) -> 1.3293501 | O11: =N11/ABS(K11) -> 0.2045154 | P11: =POWER(M11,2) -> 1.7671717 | Q11: =POWER(LOG10(1+K11)-LOG10(1+L11),2) -> 0.0050221989 | R11: =POWER(K11-$M$1,2) -> 0.091737116 | S11: =ABS(K11-$M$1) -> 0.30288136
A12: Long An | B12: Tây | C12: Tây | E12: 151 | F12: 4 | G12: 6 | H12: 2 | I12: 4 | J12: 3 | K12: 3.2 | L12: =D10+SUMPRODUCT($E$1:$J$1,E12:J12) -> 5.6043316 | M12: =K12-L12 -> -2.4043316 | N12: =ABS(M12) -> 2.4043316 | O12: =N12/ABS(K12) -> 0.75135363 | P12: =POWER(M12,2) -> 5.7808105 | Q12: =POWER(LOG10(1+K12)-LOG10(1+L12),2) -> 0.038643532 | R12: =POWER(K12-$M$1,2) -> 8.9827202 | S12: =ABS(K12-$M$1) -> 2.9971186
A13: Hà Nội | B13: Tây - Bắc | C13: Tây - Bắc | E13: 33 | F13: 3 | G13: 2 | H13: 5 | I13: 3 | J13: 4 | K13: 4.48 | L13: =D11+SUMPRODUCT($E$1:$J$1,E13:J13) -> 5.4995778 | M13: =K13-L13 -> -1.0195778 | N13: =ABS(M13) -> 1.0195778 | O13: =N13/ABS(K13) -> 0.22758432 | P13: =POWER(M13,2) -> 1.0395388 | Q13: =POWER(LOG10(1+K13)-LOG10(1+L13),2) -> 0.0054914896 | R13: =POWER(K13-$M$1,2) -> 2.9484964 | S13: =ABS(K13-$M$1) -> 1.7171186
A14: Hồ Chí Minh | B14: Đông - Bắc | C14: Đông - Bắc | E14: 38 | F14: 4.2 | G14: 6 | H14: 4 | I14: 3 | J14: 4 | K14: 6.78 | L14: =D12+SUMPRODUCT($E$1:$J$1,E14:J14) -> 5.5056153 | M14: =K14-L14 -> 1.2743847 | N14: =ABS(M14) -> 1.2743847 | O14: =N14/ABS(K14) -> 0.18796234 | P14: =POWER(M14,2) -> 1.6240563 | Q14: =POWER(LOG10(1+K14)-LOG10(1+L14),2) -> 0.0060359251 | R14: =POWER(K14-$M$1,2) -> 0.33975068 | S14: =ABS(K14-$M$1) -> 0.58288136
... A61: Hà Nội | B61: Tây - Bắc | C61: Tây - Bắc | E61: 53 | F61: 3.5 | G61: 7 | H61: 5 | I61: 8 | J61: 5 | K61: 8.8 | L61: =D59+SUMPRODUCT($E$1:$J$1,E61:J61) -> 8.7567125 | M61: =K61-L61 -> 0.043287544 | N61: =ABS(M61) -> 0.043287544 | O61: =N61/ABS(K61) -> 0.004919039 | P61: =POWER(M61,2) -> 0.0018738114 | Q61: =POWER(LOG10(1+K61)-LOG10(1+L61),2) -> 3.6962745e-06 | R61: =POWER(K61-$M$1,2) -> 6.7749914 | S61: =ABS(K61-$M$1) -> 2.6028814

Sheet danh-gia
A1: n | B1: =COUNT(data!K3:K61) -> 59 | D1: k= | E1: 6
A2: y mean | B2: =AVERAGE(data!L3:L61) -> 6.2570024
A4: 1.1.Các tiêu chí dựa trên sai số tuyệt đối
A5: Mean Absolute Error – MAE | B5: =AVERAGE(data!N3:N61) -> 1.490444 | D5: càng gần 0 càng tốt
A6: Median Absolute Error – MEDAE | B6: =MEDIAN(data!N3:N61) -> 1.3976489 | D6: càng gần 0 càng tốt, MAE và MEDAE càng gần nhau càng tốt | F6: MAE
A7: Sum of Absolute Errors – SAE | B7: =SUM(data!N3:N61) -> 87.936196 | D7: càng gần 0 càng tốt
A8: Mean Absolute Percentage Error - MAPE | B8: =AVERAGE(data!O3:O61)*100 -> 31.299426 | C8: % | D8: càng gần 0 càng tốt
A10: 1.2 Các tiêu chí dựa trên bình phương phương sai tuyệt đối
A11: Mean Squared Error – MSE | B11: =AVERAGE(data!P3:P61) -> 3.2213113 | D11: càng gần 0 càng tốt
A12: Median Squared Error – MedSE | B12: =MEDIAN(data!P3:P61) -> 1.9534225
A13: Sum of Squared Errors – SSE | B13: =SUM(data!P3:P61) -> 190.05736
A14: Root Mean Squared Error – RMSE | B14: =SQRT(B11) -> 1.7948012
A15: Mean Squared Logarithmic Error MSLE | B15: =AVERAGE(data!Q3:Q61) -> 0.015223475
A16: RMSLE | B16: =SQRT(B15) -> 0.12338345
A18: 1.3. R Square khảo sát sai số tương đối
A19: Relative Root Squared Error- RRSE | B19: =SQRT(B13/SUM(data!R3:R61)) -> 0.75914762
A20: Relative Absolute Error – RAE | B20: =B7/SUM(data!S3:S61) -> 0.73794011
A21: R- Squared (𝐑𝟐 ) | B21: =1-SUM(data!P3:P61)/SUM(data!R3:R61) -> 0.42369489
A22: (công thức trong sách sai)
A23: Adjusted R² | B23: =1-((1-B21)*(B1-1)/(B1-E1-1)) -> 0.35719814
A26: Multiple R
