Workbook

Sheet Data
A1: sex | B1: car | C1: income | D1: income_type | E1: education | F1: family_status | G1: house | H1: organization | I1: contract_x | J1: amount | K1: down_payment | L1: start_day_x | M1: purpose | N1: contract_status | O1: payment_type | P1: reject_reason | Q1: label_refused
A2: M | B2: N | C2: 202500 | D2: Working | E2: Secondary / secondary special | F2: Single / not married | G2: House / apartment | H2: Business Entity Type 3 | I2: Consumer loans | J2: 179055 | K2: 0 | L2: SATURDAY | M2: XAP | N2: Approved | O2: XNA | P2: XAP | Q2: 0
A3: F | B3: N | C3: 270000 | D3: State servant | E3: Higher education | F3: Married | G3: House / apartment | H3: School | I3: Consumer loans | J3: 337500 | K3: 0 | L3: SUNDAY | M3: XAP | N3: Approved | O3: Cash through the bank | P3: XAP | Q3: 0
A4: M | B4: Y | C4: 67500 | D4: Working | E4: Secondary / secondary special | F4: Single / not married | G4: House / apartment | H4: Government | I4: Consumer loans | J4: 24282 | K4: 4860 | L4: FRIDAY | M4: XAP | N4: Approved | O4: Cash through the bank | P4: XAP | Q4: 0
A5: F | B5: N | C5: 135000 | D5: Working | E5: Secondary / secondary special | F5: Civil marriage | G5: House / apartment | H5: Business Entity Type 3 | I5: Consumer loans | J5: 334917 | K5: 66987 | L5: SUNDAY | M5: XAP | N5: Approved | O5: Cash through the bank | P5: XAP | Q5: 0
A6: M | B6: N | C6: 99000 | D6: State servant | E6: Secondary / secondary special | F6: Married | G6: House | H6: Other | I6: Consumer loans | J6: 162598.5 | K6: 0 | L6: THURSDAY | M6: XAP | N6: Approved | O6: Cash through the bank | P6: XAP | Q6: 0
A7: M | B7: N | C7: 99000 | D7: State servant | E7: Secondary / secondary special | F7: Married | G7: House | H7: Other | I7: Consumer loans | J7: 44455.5 | K7: 4500 | L7: MONDAY | M7: XAP | N7: Approved | O7: Cash through the bank | P7: XAP | Q7: 0
A8: M | B8: N | C8: 99000 | D8: State servant | E8: Secondary / secondary special | F8: Married | G8: House | H8: Other | I8: Consumer loans | J8: 121455 | K8: 12145.5 | L8: MONDAY | M8: XAP | N8: Approved | O8: Cash through the bank | P8: XAP | Q8: 0
A9: F | B9: Y | C9: 171000 | D9: Commercial associate | E9: Higher education | F9: Married | G9: House / apartment | H9: Business Entity Type 3 | I9: Consumer loans | J9: 98239.5 | K9: 0 | L9: SATURDAY | M9: XAP | N9: Approved | O9: Cash through the bank | P9: XAP | Q9: 0
A10: F | B10: Y | C10: 171000 | D10: Commercial associate | E10: Higher education | F10: Married | G10: House / apartment | H10: Business Entity Type 3 | I10: Consumer loans | J10: 46876.5 | K10: 4689 | L10: WEDNESDAY | M10: XAP | N10: Approved | O10: Cash through the bank | P10: XAP | Q10: 0
A11: F | B11: Y | C11: 171000 | D11: Commercial associate | E11: Higher education | F11: Married | G11: House / apartment | H11: Business Entity Type 3 | I11: Consumer loans | J11: 47160 | K11: 9432 | L11: SUNDAY | M11: XAP | N11: Approved | O11: Cash through the bank | P11: XAP | Q11: 0
A12: F | B12: N | C12: 112500 | D12: Pensioner | E12: Secondary / secondary special | F12: Married | G12: House / apartment | H12: XNA | I12: Consumer loans | J12: 135931.5 | K12: 13594.5 | L12: MONDAY | M12: XAP | N12: Approved | O12: Cash through the bank | P12: XAP | Q12: 0
A13: M | B13: N | C13: 135000 | D13: Working | E13: Secondary / secondary special | F13: Single / not married | G13: House / apartment | H13: Electricity | I13: Consumer loans | J13: 18720 | K13: 0 | L13: THURSDAY | M13: XAP | N13: Approved | O13: XNA | P13: XAP | Q13: 0
... A1961: M | B1961: Y | C1961: 166500 | D1961: Pensioner | E1961: Higher education | F1961: Married | G1961: House / apartment | H1961: XNA | I1961: Consumer loans | J1961: 29232 | K1961: 0 | L1961: SATURDAY | M1961: XAP | N1961: Unused offer | O1961: Cash through the bank | P1961: CLIENT | Q1961: 0

Sheet Data-LR
A1: income | B1: amount | C1: down_payment | D1: label_refused
A2: 202500 | B2: 179055 | C2: 0 | D2: 0
A3: 270000 | B3: 337500 | C3: 0 | D3: 0
A4: 67500 | B4: 24282 | C4: 4860 | D4: 0
A5: 135000 | B5: 334917 | C5: 66987 | D5: 0
A6: 99000 | B6: 162598.5 | C6: 0 | D6: 0
A7: 99000 | B7: 44455.5 | C7: 4500 | D7: 0
A8: 99000 | B8: 121455 | C8: 12145.5 | D8: 0
A9: 171000 | B9: 98239.5 | C9: 0 | D9: 0
A10: 171000 | B10: 46876.5 | C10: 4689 | D10: 0
A11: 171000 | B11: 47160 | C11: 9432 | D11: 0
A12: 112500 | B12: 135931.5 | C12: 13594.5 | D12: 0
A13: 135000 | B13: 18720 | C13: 0 | D13: 0
... A1961: 166500 | B1961: 29232 | C1961: 0 | D1961: 0

Sheet Data-LR-Short-Train
A1: income | B1: amount | C1: down_payment | D1: label_refused | F1: Mô tả dữ liệu
A2: 540000 | B2: 54202.5 | C2: 5422.5 | D2: 1 | F2: tổng số mẫu n= | H2: =COUNT(A2:A31) -> 30
A3: 180000 | B3: 125941.5 | C3: 13360.5 | D3: 1 | F3: X= | G3: (income, amount, down_payment)
A4: 225000 | B4: 58590 | C4: 5859 | D4: 1 | G4: (thu nhập, số tiền vay, khoản trả trước)
A5: 180000 | B5: 19030.5 | C5: 1903.5 | D5: 1 | F5: y= | G5: label_refused
A6: 450000 | B6: 169636.5 | C6: 16965 | D6: 0 | G6: bị từ chối khoản vay, được gán nhãn
A7: 225000 | B7: 44055 | C7: 4405.5 | D7: 0 | G7: =1 nếu bị từ chối, =0 ngược lại
A8: 157500 | B8: 29587.5 | C8: 2961 | D8: 1 | F8: mean và variance của income
A9: 90000 | B9: 33660 | C9: 3366 | D9: 1 | F9: μ1 | G9: σ1
A10: 189000 | B10: 45810 | C10: 4581 | D10: 0 | F10: =AVERAGE(A2:A32) -> 183150 | G10: =_xlfn.STDEV.P(A2:A32) -> 94665.213
A11: 67500 | B11: 97357.5 | C11: 9738 | D11: 0 | F11: mean và variance của amount
A12: 135000 | B12: 18445.5 | C12: 1845 | D12: 0 | F12: μ2 | G12: σ2
A13: 180000 | B13: 27675 | C13: 6750 | D13: 1 | F13: =AVERAGE(B2:B32) -> 64010.517 | G13: =_xlfn.STDEV.P(B2:B32) -> 38347.25
A14: 225000 | B14: 29745 | C14: 5949 | D14: 0 | F14: mean và variance của downpayment
A15: 126000 | B15: 19750.455 | C15: 4.455 | D15: 0 | F15: μ3 | G15: σ3
A16: 126000 | B16: 50625 | C16: 5062.5 | D16: 0 | F16: =AVERAGE(C2:C32) -> 8901.567 | G16: =_xlfn.STDEV.P(C2:C32) -> 12365.062
A17: 247500 | B17: 92146.5 | C17: 9216 | D17: 1
A18: 171000 | B18: 82665 | C18: 8266.5 | D18: 0 | F18: Sale X với mean và variance
A19: 135000 | B19: 56205 | C19: 5400 | D19: 0
A20: 157500 | B20: 143460 | C20: 71730 | D20: 1
A21: 184500 | B21: 24367.5 | C21: 3690 | D21: 0
A22: 225000 | B22: 106186.5 | C22: 10620 | D22: 1
A23: 135000 | B23: 27162 | C23: 4500 | D23: 1
A24: 180000 | B24: 67679.955 | C24: 6772.455 | D24: 1
A25: 135000 | B25: 43560 | C25: 4356 | D25: 1
A26: 99000 | B26: 105057 | C26: 11250 | D26: 1
A27: 157500 | B27: 79443 | C27: 7947 | D27: 0
A28: 180000 | B28: 87259.5 | C28: 8730 | D28: 0
A29: 180000 | B29: 47927.7 | C29: 4795.2 | D29: 0
A30: 108000 | B30: 44973.9 | C30: 3600.9 | D30: 1
A31: 103500 | B31: 88110 | C31: 18000 | D31: 0

Sheet Logistic-Regression
A1: X0 | B1: X1 | C1: X2 | D1: X3 | E1: y | F1: Lặp lần 1 | G1: Lần lặp 1 | S1: Lặp lần 2 | T1: Lần lặp 2 | AF1: Lặp lần 3 | AG1: Lần lặp 3
B2: income | C2: amount | D2: down_payment | E2: label_refused | G2: ϐ0 | H2: 0 | I2: z | J2: ŷ | K2: ŷ - y | L2: (ŷ - y)X0 | M2: (ŷ - y)X1 | N2: (ŷ - y)X2 | O2: (ŷ - y)X3 | P2: 𝓛(β)-i | Q2: ∇𝓛(β0) | R2: =(1/$C$36)*SUM(L3:L32) -> 0 | T2: ϐ0 | U2: =H2-$R$6*R2 -> 0 | V2: z | W2: ŷ | X2: ŷ - y | Y2: (ŷ - y)X0 | Z2: (ŷ - y)X1 | AA2: (ŷ - y)X2 | AB2: (ŷ - y)X3 | AC2: 𝓛(β)-i | AD2: ∇𝓛(β0) | AE2: =(1/$C$36)*SUM(Y3:Y32) -> -5.1043469e-11 | AG2: ϐ0 | AH2: =U2-$AE$6*AE2 -> 5.1043469e-13 | AI2: z | AJ2: ŷ | AK2: ŷ - y | AL2: (ŷ - y)X0 | AM2: (ŷ - y)X1 | AN2: (ŷ - y)X2 | AO2: (ŷ - y)X3 | AP2: 𝓛(β)-i | AQ2: ∇𝓛(β0) | AR2: =(1/$C$36)*SUM(AL3:AL32) -> -4.0601024e-10 | AT2: -4.0601024e-10 | AU2: =AR2-AT2 -> 0
A3: 1 | B3: =('Data-LR-Short-Train'!A2-'Data-LR-Short-Train'!$F$10)/'Data-LR-Short-Train'!$G$10 -> 3.7696001 | C3: =('Data-LR-Short-Train'!B2-'Data-LR-Short-Train'!$F$13)/'Data-LR-Short-Train'!$G$13 -> -0.25576846 | D3: =('Data-LR-Short-Train'!C2-'Data-LR-Short-Train'!$F$16)/'Data-LR-Short-Train'!$G$16 -> -0.28136268 | E3: ='Data-LR-Short-Train'!D2 -> 1 | G3: ϐ1 | H3: 0 | I3: =H$2+H$3*$B3+H$4*$C3+H$5*$D3 -> 0 | J3: =1/(1+EXP(-I3)) -> 0.5 | K3: =J3-$E3 -> -0.5 | L3: =$K3*A3 -> -0.5 | M3: =$K3*B3 -> -1.8848001 | N3: =$K3*C3 -> 0.12788423 | O3: =$K3*D3 -> 0.14068134 | P3: =$E3*LN(J3)+(1-$E3)*LN(1-J3) -> -0.69314718 | Q3: ∇𝓛(β1) | R3: =(1/$C$36)*SUM(M3:M32) -> -0.032482893 | T3: ϐ1 | U3: =H3-$R$6*R3 -> 0.00032482893 | V3: =U$2+ U$3*$B3+U$4*$C3+U$5*$D3 -> 0.00096930598 | W3: =1/(1+EXP(-V3)) -> 0.50024233 | X3: =W3-$E3 -> -0.49975767 | Y3: =$X3*A3 -> -0.49975767 | Z3: =$X3*B3 -> -1.8838866 | AA3: =$X3*C3 -> 0.12782225 | AB3: =$X3*D3 -> 0.14061316 | AC3: =$E3*LN(W3)+(1-$E3)*LN(1-W3) -> -0.69266265 | AD3: ∇𝓛(β1) | AE3: =(1/$C$36)*SUM(Z3:Z32) -> -0.032387606 | AG3: ϐ1 | AH3: =U3-$AE$6*AE3 -> 0.00064870499 | AI3: =AH$2+ AH$3*$B3+AH$4*$C3+AH$5*$D3 -> 0.001936095 | AJ3: =1/(1+EXP(-AI3)) -> 0.50048402 | AK3: =AJ3-$E3 -> -0.49951598 | AL3: =$AK3*A3 -> -0.49951598 | AM3: =$AK3*B3 -> -1.8829755 | AN3: =$AK3*C3 -> 0.12776043 | AO3: =$AK3*D3 -> 0.14054515 | AP3: =$E3*LN(AJ3)+(1-$E3)*LN(1-AJ3) -> -0.6921796 | AQ3: ∇𝓛(β1) | AR3: =(1/$C$36)*SUM(AM3:AM32) -> -0.032292682 | AT3: -0.032292682 | AU3: =AR3-AT3 -> 0
A4: 1 | B4: =('Data-LR-Short-Train'!A3-'Data-LR-Short-Train'!$F$10)/'Data-LR-Short-Train'!$G$10 -> -0.033275159 | C4: =('Data-LR-Short-Train'!B3-'Data-LR-Short-Train'!$F$13)/'Data-LR-Short-Train'!$G$13 -> 1.6150045 | D4: =('Data-LR-Short-Train'!C3-'Data-LR-Short-Train'!$F$16)/'Data-LR-Short-Train'!$G$16 -> 0.36060741 | E4: ='Data-LR-Short-Train'!D3 -> 1 | G4: ϐ2 | H4: 0 | I4: =H$2+ H$3*$B4+H$4*$C4+H$5*$D4 -> 0 | J4: =1/(1+EXP(-I4)) -> 0.5 | K4: =J4-$E4 -> -0.5 | L4: =$K4*A4 -> -0.5 | M4: =$K4*B4 -> 0.016637579 | N4: =$K4*C4 -> -0.80750227 | O4: =$K4*D4 -> -0.1803037 | P4: =$E4*LN(J4)+(1-$E4)*LN(1-J4) -> -0.69314718 | Q4: ∇𝓛(β2) | R4: =(1/$C$36)*SUM(N3:N32) -> -0.016302864 | T4: ϐ2 | U4: =H4-$R$6*R4 -> 0.00016302864 | V4: =U$2+ U$3*$B4+U$4*$C4+U$5*$D4 -> 0.00052607836 | W4: =1/(1+EXP(-V4)) -> 0.50013152 | X4: =W4-$E4 -> -0.49986848 | Y4: =$X4*A4 -> -0.49986848 | Z4: =$X4*B4 -> 0.016633203 | AA4: =$X4*C4 -> -0.80728987 | AB4: =$X4*D4 -> -0.18025628 | AC4: =$E4*LN(W4)+(1-$E4)*LN(1-W4) -> -0.69288418 | AD4: ∇𝓛(β2) | AE4: =(1/$C$36)*SUM(AA3:AA32) -> -0.016121398 | AG4: ϐ2 | AH4: =U4-$AE$6*AE4 -> 0.00032424262 | AI4: =AH$2+ AH$3*$B4+AH$4*$C4+AH$5*$D4 -> 0.0010484748 | AJ4: =1/(1+EXP(-AI4)) -> 0.50026212 | AK4: =AJ4-$E4 -> -0.49973788 | AL4: =$AK4*A4 -> -0.49973788 | AM4: =$AK4*B4 -> 0.016628857 | AN4: =$AK4*C4 -> -0.80707895 | AO4: =$AK4*D4 -> -0.18020918 | AP4: =$E4*LN(AJ4)+(1-$E4)*LN(1-AJ4) -> -0.69262308 | AQ4: ∇𝓛(β2) | AR4: =(1/$C$36)*SUM(AN3:AN32) -> -0.015940791 | AT4: -0.015940791 | AU4: =AR4-AT4 -> 0
A5: 1 | B5: =('Data-LR-Short-Train'!A4-'Data-LR-Short-Train'!$F$10)/'Data-LR-Short-Train'!$G$10 -> 0.44208425 | C5: =('Data-LR-Short-Train'!B4-'Data-LR-Short-Train'!$F$13)/'Data-LR-Short-Train'!$G$13 -> -0.14135347 | D5: =('Data-LR-Short-Train'!C4-'Data-LR-Short-Train'!$F$16)/'Data-LR-Short-Train'!$G$16 -> -0.2460616 | E5: ='Data-LR-Short-Train'!D4 -> 1 | G5: ϐ3 | H5: 0 | I5: =H$2+ H$3*$B5+H$4*$C5+H$5*$D5 -> 0 | J5: =1/(1+EXP(-I5)) -> 0.5 | K5: =J5-$E5 -> -0.5 | L5: =$K5*A5 -> -0.5 | M5: =$K5*B5 -> -0.22104213 | N5: =$K5*C5 -> 0.070676737 | O5: =$K5*D5 -> 0.1230308 | P5: =$E5*LN(J5)+(1-$E5)*LN(1-J5) -> -0.69314718 | Q5: ∇𝓛(β3) | R5: =(1/$C$36)*SUM(O3:O32) -> -0.075870626 | T5: ϐ3 | U5: =H5-$R$6*R5 -> 0.00075870626 | V5: =U$2+ U$3*$B5+U$4*$C5+U$5*$D5 -> -6.6131387e-05 | W5: =1/(1+EXP(-V5)) -> 0.49998347 | X5: =W5-$E5 -> -0.50001653 | Y5: =$X5*A5 -> -0.50001653 | Z5: =$X5*B5 -> -0.22104944 | AA5: =$X5*C5 -> 0.070679074 | AB5: =$X5*D5 -> 0.12303487 | AC5: =$E5*LN(W5)+(1-$E5)*LN(1-W5) -> -0.69318025 | AD5: ∇𝓛(β3) | AE5: =(1/$C$36)*SUM(AB3:AB32) -> -0.075653501 | AG5: ϐ3 | AH5: =U5-$AE$6*AE5 -> 0.0015152413 | AI5: =AH$2+ AH$3*$B5+AH$4*$C5+AH$5*$D5 -> -0.00013189326 | AJ5: =1/(1+EXP(-AI5)) -> 0.49996703 | AK5: =AJ5-$E5 -> -0.50003297 | AL5: =$AK5*A5 -> -0.50003297 | AM5: =$AK5*B5 -> -0.2210567 | AN5: =$AK5*C5 -> 0.070681398 | AO5: =$AK5*D5 -> 0.12303892 | AP5: =$E5*LN(AJ5)+(1-$E5)*LN(1-AJ5) -> -0.69321313 | AQ5: ∇𝓛(β3) | AR5: =(1/$C$36)*SUM(AO3:AO32) -> -0.075437212 | AT5: -0.075437212 | AU5: =AR5-AT5 -> 0
A6: 1 | B6: =('Data-LR-Short-Train'!A5-'Data-LR-Short-Train'!$F$10)/'Data-LR-Short-Train'!$G$10 -> -0.033275159 | C6: =('Data-LR-Short-Train'!B5-'Data-LR-Short-Train'!$F$13)/'Data-LR-Short-Train'!$G$13 -> -1.1729659 | D6: =('Data-LR-Short-Train'!C5-'Data-LR-Short-Train'!$F$16)/'Data-LR-Short-Train'!$G$16 -> -0.56595486 | E6: ='Data-LR-Short-Train'!D5 -> 1 | I6: =H$2+ H$3*$B6+H$4*$C6+H$5*$D6 -> 0 | J6: =1/(1+EXP(-I6)) -> 0.5 | K6: =J6-$E6 -> -0.5 | L6: =$K6*A6 -> -0.5 | M6: =$K6*B6 -> 0.016637579 | N6: =$K6*C6 -> 0.58648296 | O6: =$K6*D6 -> 0.28297743 | P6: =$E6*LN(J6)+(1-$E6)*LN(1-J6) -> -0.69314718 | Q6: α = η | R6: =C38 -> 0.01 | V6: =U$2+ U$3*$B6+U$4*$C6+U$5*$D6 -> -0.00063142927 | W6: =1/(1+EXP(-V6)) -> 0.49984214 | X6: =W6-$E6 -> -0.50015786 | Y6: =$X6*A6 -> -0.50015786 | Z6: =$X6*B6 -> 0.016642832 | AA6: =$X6*C6 -> 0.58666812 | AB6: =$X6*D6 -> 0.28306677 | AC6: =$E6*LN(W6)+(1-$E6)*LN(1-W6) -> -0.69346295 | AD6: α = η | AE6: 0.01 | AI6: =AH$2+ AH$3*$B6+AH$4*$C6+AH$5*$D6 -> -0.0012594695 | AJ6: =1/(1+EXP(-AI6)) -> 0.49968513 | AK6: =AJ6-$E6 -> -0.50031487 | AL6: =$AK6*A6 -> -0.50031487 | AM6: =$AK6*B6 -> 0.016648057 | AN6: =$AK6*C6 -> 0.58685229 | AO6: =$AK6*D6 -> 0.28315563 | AP6: =$E6*LN(AJ6)+(1-$E6)*LN(1-AJ6) -> -0.69377711 | AQ6: α = η | AR6: 0.01
A7: 1 | B7: =('Data-LR-Short-Train'!A6-'Data-LR-Short-Train'!$F$10)/'Data-LR-Short-Train'!$G$10 -> 2.8188813 | C7: =('Data-LR-Short-Train'!B6-'Data-LR-Short-Train'!$F$13)/'Data-LR-Short-Train'!$G$13 -> 2.7544604 | D7: =('Data-LR-Short-Train'!C6-'Data-LR-Short-Train'!$F$16)/'Data-LR-Short-Train'!$G$16 -> 0.65211424 | E7: ='Data-LR-Short-Train'!D6 -> 0 | I7: =H$2+ H$3*$B7+H$4*$C7+H$5*$D7 -> 0 | J7: =1/(1+EXP(-I7)) -> 0.5 | K7: =J7-$E7 -> 0.5 | L7: =$K7*A7 -> 0.5 | M7: =$K7*B7 -> 1.4094407 | N7: =$K7*C7 -> 1.3772302 | O7: =$K7*D7 -> 0.32605712 | P7: =$E7*LN(J7)+(1-$E7)*LN(1-J7) -> -0.69314718 | Q7: ε | R7: 0.001 | V7: =U$2+ U$3*$B7+U$4*$C7+U$5*$D7 -> 0.0018594733 | W7: =1/(1+EXP(-V7)) -> 0.50046487 | X7: =W7-$E7 -> 0.50046487 | Y7: =$X7*A7 -> 0.50046487 | Z7: =$X7*B7 -> 1.4107511 | AA7: =$X7*C7 -> 1.3785107 | AB7: =$X7*D7 -> 0.32636027 | AC7: =$E7*LN(W7)+(1-$E7)*LN(1-W7) -> -0.69407735 | AD7: ε | AE7: 0.001 | AI7: =AH$2+ AH$3*$B7+AH$4*$C7+AH$5*$D7 -> 0.0037098463 | AJ7: =1/(1+EXP(-AI7)) -> 0.50092746 | AK7: =AJ7-$E7 -> 0.50092746 | AL7: =$AK7*A7 -> 0.50092746 | AM7: =$AK7*B7 -> 1.4120551 | AN7: =$AK7*C7 -> 1.3797849 | AO7: =$AK7*D7 -> 0.32666193 | AP7: =$E7*LN(AJ7)+(1-$E7)*LN(1-AJ7) -> -0.69500382 | AQ7: ε | AR7: 0.001
A8: 1 | B8: =('Data-LR-Short-Train'!A7-'Data-LR-Short-Train'!$F$10)/'Data-LR-Short-Train'!$G$10 -> 0.44208425 | C8: =('Data-LR-Short-Train'!B7-'Data-LR-Short-Train'!$F$13)/'Data-LR-Short-Train'!$G$13 -> -0.52038978 | D8: =('Data-LR-Short-Train'!C7-'Data-LR-Short-Train'!$F$16)/'Data-LR-Short-Train'!$G$16 -> -0.36361055 | E8: ='Data-LR-Short-Train'!D7 -> 0 | I8: =H$2+ H$3*$B8+H$4*$C8+H$5*$D8 -> 0 | J8: =1/(1+EXP(-I8)) -> 0.5 | K8: =J8-$E8 -> 0.5 | L8: =$K8*A8 -> 0.5 | M8: =$K8*B8 -> 0.22104213 | N8: =$K8*C8 -> -0.26019489 | O8: =$K8*D8 -> -0.18180527 | P8: =$E8*LN(J8)+(1-$E8)*LN(1-J8) -> -0.69314718 | Q8: ‖∇L(β)‖ | R8: =SQRT(R2^2 + R3^2 + R4^2 +R5^2) -> 0.084126533 | V8: =U$2+ U$3*$B8+U$4*$C8+U$5*$D8 -> -0.00021711028 | W8: =1/(1+EXP(-V8)) -> 0.49994572 | X8: =W8-$E8 -> 0.49994572 | Y8: =$X8*A8 -> 0.49994572 | Z8: =$X8*B8 -> 0.22101813 | AA8: =$X8*C8 -> -0.26016665 | AB8: =$X8*D8 -> -0.18178554 | AC8: =$E8*LN(W8)+(1-$E8)*LN(1-W8) -> -0.69303863 | AD8: ‖∇L(β)‖ | AE8: =SQRT(AE2^2 + AE3^2 + AE4^2 +AE5^2) -> 0.083858862 | AI8: =AH$2+ AH$3*$B8+AH$4*$C8+AH$5*$D8 -> -0.000432908 | AJ8: =1/(1+EXP(-AI8)) -> 0.49989177 | AK8: =AJ8-$E8 -> 0.49989177 | AL8: =$AK8*A8 -> 0.49989177 | AM8: =$AK8*B8 -> 0.22099428 | AN8: =$AK8*C8 -> -0.26013857 | AO8: =$AK8*D8 -> -0.18176592 | AP8: =$E8*LN(AJ8)+(1-$E8)*LN(1-AJ8) -> -0.69293075 | AQ8: ‖∇L(β)‖ | AR8: =SQRT(AR2^2 + AR3^2 + AR4^2 +AR5^2) -> 0.083592458
A9: 1 | B9: =('Data-LR-Short-Train'!A8-'Data-LR-Short-Train'!$F$10)/'Data-LR-Short-Train'!$G$10 -> -0.27095487 | C9: =('Data-LR-Short-Train'!B8-'Data-LR-Short-Train'!$F$13)/'Data-LR-Short-Train'!$G$13 -> -0.89766586 | D9: =('Data-LR-Short-Train'!C8-'Data-LR-Short-Train'!$F$16)/'Data-LR-Short-Train'!$G$16 -> -0.48043164 | E9: ='Data-LR-Short-Train'!D8 -> 1 | I9: =H$2+ H$3*$B9+H$4*$C9+H$5*$D9 -> 0 | J9: =1/(1+EXP(-I9)) -> 0.5 | K9: =J9-$E9 -> -0.5 | L9: =$K9*A9 -> -0.5 | M9: =$K9*B9 -> 0.13547743 | N9: =$K9*C9 -> 0.44883293 | O9: =$K9*D9 -> 0.24021582 | P9: =$E9*LN(J9)+(1-$E9)*LN(1-J9) -> -0.69314718 | Q9: 𝓛(β) | R9: =(-1/$C$36)*SUM(P3:P32) -> 0.69314718 | V9: =U$2+ U$3*$B9+U$4*$C9+U$5*$D9 -> -0.00059886571 | W9: =1/(1+EXP(-V9)) -> 0.49985028 | X9: =W9-$E9 -> -0.50014972 | Y9: =$X9*A9 -> -0.50014972 | Z9: =$X9*B9 -> 0.135518 | AA9: =$X9*C9 -> 0.44896732 | AB9: =$X9*D9 -> 0.24028775 | AC9: =$E9*LN(W9)+(1-$E9)*LN(1-W9) -> -0.69344666 | AD9: 𝓛(β) | AE9: =(-1/$C$36)*SUM(AC3:AC32) -> 0.69307652 | AI9: =AH$2+ AH$3*$B9+AH$4*$C9+AH$5*$D9 -> -0.0011948011 | AJ9: =1/(1+EXP(-AI9)) -> 0.4997013 | AK9: =AJ9-$E9 -> -0.5002987 | AL9: =$AK9*A9 -> -0.5002987 | AM9: =$AK9*B9 -> 0.13555837 | AN9: =$AK9*C9 -> 0.44910106 | AO9: =$AK9*D9 -> 0.24035932 | AP9: =$E9*LN(AJ9)+(1-$E9)*LN(1-AJ9) -> -0.69374476 | AQ9: 𝓛(β) | AR9: =(-1/$C$36)*SUM(AP3:AP32) -> 0.69300631
A10: 1 | B10: =('Data-LR-Short-Train'!A9-'Data-LR-Short-Train'!$F$10)/'Data-LR-Short-Train'!$G$10 -> -0.98399399 | C10: =('Data-LR-Short-Train'!B9-'Data-LR-Short-Train'!$F$13)/'Data-LR-Short-Train'!$G$13 -> -0.79146528 | D10: =('Data-LR-Short-Train'!C9-'Data-LR-Short-Train'!$F$16)/'Data-LR-Short-Train'!$G$16 -> -0.44767806 | E10: ='Data-LR-Short-Train'!D9 -> 1 | I10: =H$2+ H$3*$B10+H$4*$C10+H$5*$D10 -> 0 | J10: =1/(1+EXP(-I10)) -> 0.5 | K10: =J10-$E10 -> -0.5 | L10: =$K10*A10 -> -0.5 | M10: =$K10*B10 -> 0.49199699 | N10: =$K10*C10 -> 0.39573264 | O10: =$K10*D10 -> 0.22383903 | P10: =$E10*LN(J10)+(1-$E10)*LN(1-J10) -> -0.69314718 | V10: =U$2+ U$3*$B10+U$4*$C10+U$5*$D10 -> -0.00078831737 | W10: =1/(1+EXP(-V10)) -> 0.49980292 | X10: =W10-$E10 -> -0.50019708 | Y10: =$X10*A10 -> -0.50019708 | Z10: =$X10*B10 -> 0.49219092 | AA10: =$X10*C10 -> 0.39588862 | AB10: =$X10*D10 -> 0.22392726 | AC10: =$E10*LN(W10)+(1-$E10)*LN(1-W10) -> -0.69354142 | AI10: =AH$2+ AH$3*$B10+AH$4*$C10+AH$5*$D10 -> -0.0015732889 | AJ10: =1/(1+EXP(-AI10)) -> 0.49960668 | AK10: =AJ10-$E10 -> -0.50039332 | AL10: =$AK10*A10 -> -0.50039332 | AM10: =$AK10*B10 -> 0.49238402 | AN10: =$AK10*C10 -> 0.39604394 | AO10: =$AK10*D10 -> 0.22401511 | AP10: =$E10*LN(AJ10)+(1-$E10)*LN(1-AJ10) -> -0.69393413
A11: 1 | B11: =('Data-LR-Short-Train'!A10-'Data-LR-Short-Train'!$F$10)/'Data-LR-Short-Train'!$G$10 -> 0.061796724 | C11: =('Data-LR-Short-Train'!B10-'Data-LR-Short-Train'!$F$13)/'Data-LR-Short-Train'!$G$13 -> -0.47462379 | D11: =('Data-LR-Short-Train'!C10-'Data-LR-Short-Train'!$F$16)/'Data-LR-Short-Train'!$G$16 -> -0.34941733 | E11: ='Data-LR-Short-Train'!D10 -> 0 | I11: =H$2+ H$3*$B11+H$4*$C11+H$5*$D11 -> 0 | J11: =1/(1+EXP(-I11)) -> 0.5 | K11: =J11-$E11 -> 0.5 | L11: =$K11*A11 -> 0.5 | M11: =$K11*B11 -> 0.030898362 | N11: =$K11*C11 -> -0.23731189 | O11: =$K11*D11 -> -0.17470867 | P11: =$E11*LN(J11)+(1-$E11)*LN(1-J11) -> -0.69314718 | V11: =U$2+ U$3*$B11+U$4*$C11+U$5*$D11 -> -0.00032240902 | W11: =1/(1+EXP(-V11)) -> 0.4999194 | X11: =W11-$E11 -> 0.4999194 | Y11: =$X11*A11 -> 0.4999194 | Z11: =$X11*B11 -> 0.030893381 | AA11: =$X11*C11 -> -0.23727364 | AB11: =$X11*D11 -> -0.1746805 | AC11: =$E11*LN(W11)+(1-$E11)*LN(1-W11) -> -0.69298599 | AI11: =AH$2+ AH$3*$B11+AH$4*$C11+AH$5*$D11 -> -0.00064325698 | AJ11: =1/(1+EXP(-AI11)) -> 0.49983919 | AK11: =AJ11-$E11 -> 0.49983919 | AL11: =$AK11*A11 -> 0.49983919 | AM11: =$AK11*B11 -> 0.030888424 | AN11: =$AK11*C11 -> -0.23723557 | AO11: =$AK11*D11 -> -0.17465247 | AP11: =$E11*LN(AJ11)+(1-$E11)*LN(1-AJ11) -> -0.6928256
A12: 1 | B12: =('Data-LR-Short-Train'!A11-'Data-LR-Short-Train'!$F$10)/'Data-LR-Short-Train'!$G$10 -> -1.2216737 | C12: =('Data-LR-Short-Train'!B11-'Data-LR-Short-Train'!$F$13)/'Data-LR-Short-Train'!$G$13 -> 0.86960559 | D12: =('Data-LR-Short-Train'!C11-'Data-LR-Short-Train'!$F$16)/'Data-LR-Short-Train'!$G$16 -> 0.067644869 | E12: ='Data-LR-Short-Train'!D11 -> 0 | I12: =H$2+ H$3*$B12+H$4*$C12+H$5*$D12 -> 0 | J12: =1/(1+EXP(-I12)) -> 0.5 | K12: =J12-$E12 -> 0.5 | L12: =$K12*A12 -> 0.5 | M12: =$K12*B12 -> -0.61083685 | N12: =$K12*C12 -> 0.4348028 | O12: =$K12*D12 -> 0.033822434 | P12: =$E12*LN(J12)+(1-$E12)*LN(1-J12) -> -0.69314718 | V12: =U$2+ U$3*$B12+U$4*$C12+U$5*$D12 -> -0.00020374176 | W12: =1/(1+EXP(-V12)) -> 0.49994906 | X12: =W12-$E12 -> 0.49994906 | Y12: =$X12*A12 -> 0.49994906 | Z12: =$X12*B12 -> -0.61077462 | AA12: =$X12*C12 -> 0.4347585 | AB12: =$X12*D12 -> 0.033818989 | AC12: =$E12*LN(W12)+(1-$E12)*LN(1-W12) -> -0.69304531 | AI12: =AH$2+ AH$3*$B12+AH$4*$C12+AH$5*$D12 -> -0.00040804432 | AJ12: =1/(1+EXP(-AI12)) -> 0.49989799 | AK12: =AJ12-$E12 -> 0.49989799 | AL12: =$AK12*A12 -> 0.49989799 | AM12: =$AK12*B12 -> -0.61071222 | AN12: =$AK12*C12 -> 0.43471409 | AO12: =$AK12*D12 -> 0.033815534 | AP12: =$E12*LN(AJ12)+(1-$E12)*LN(1-AJ12) -> -0.69294318
A13: 1 | B13: =('Data-LR-Short-Train'!A12-'Data-LR-Short-Train'!$F$10)/'Data-LR-Short-Train'!$G$10 -> -0.50863457 | C13: =('Data-LR-Short-Train'!B12-'Data-LR-Short-Train'!$F$13)/'Data-LR-Short-Train'!$G$13 -> -1.1882212 | D13: =('Data-LR-Short-Train'!C12-'Data-LR-Short-Train'!$F$16)/'Data-LR-Short-Train'!$G$16 -> -0.57068593 | E13: ='Data-LR-Short-Train'!D12 -> 0 | I13: =H$2+ H$3*$B13+H$4*$C13+H$5*$D13 -> 0 | J13: =1/(1+EXP(-I13)) -> 0.5 | K13: =J13-$E13 -> 0.5 | L13: =$K13*A13 -> 0.5 | M13: =$K13*B13 -> -0.25431729 | N13: =$K13*C13 -> -0.59411062 | O13: =$K13*D13 -> -0.28534297 | P13: =$E13*LN(J13)+(1-$E13)*LN(1-J13) -> -0.69314718 | V13: =U$2+ U$3*$B13+U$4*$C13+U$5*$D13 -> -0.00079191631 | W13: =1/(1+EXP(-V13)) -> 0.49980202 | X13: =W13-$E13 -> 0.49980202 | Y13: =$X13*A13 -> 0.49980202 | Z13: =$X13*B13 -> -0.25421659 | AA13: =$X13*C13 -> -0.59387538 | AB13: =$X13*D13 -> -0.28522998 | AC13: =$E13*LN(W13)+(1-$E13)*LN(1-W13) -> -0.6927513 | AI13: =AH$2+ AH$3*$B13+AH$4*$C13+AH$5*$D13 -> -0.0015799526 | AJ13: =1/(1+EXP(-AI13)) -> 0.49960501 | AK13: =AJ13-$E13 -> 0.49960501 | AL13: =$AK13*A13 -> 0.49960501 | AM13: =$AK13*B13 -> -0.25411638 | AN13: =$AK13*C13 -> -0.59364129 | AO13: =$AK13*D13 -> -0.28511755 | AP13: =$E13*LN(AJ13)+(1-$E13)*LN(1-AJ13) -> -0.69235752
A14: 1 | B14: =('Data-LR-Short-Train'!A13-'Data-LR-Short-Train'!$F$10)/'Data-LR-Short-Train'!$G$10 -> -0.033275159 | C14: =('Data-LR-Short-Train'!B13-'Data-LR-Short-Train'!$F$13)/'Data-LR-Short-Train'!$G$13 -> -0.94753906 | D14: =('Data-LR-Short-Train'!C13-'Data-LR-Short-Train'!$F$16)/'Data-LR-Short-Train'!$G$16 -> -0.17400374 | E14: ='Data-LR-Short-Train'!D13 -> 1 | I14: =H$2+ H$3*$B14+H$4*$C14+H$5*$D14 -> 0 | J14: =1/(1+EXP(-I14)) -> 0.5 | K14: =J14-$E14 -> -0.5 | L14: =$K14*A14 -> -0.5 | M14: =$K14*B14 -> 0.016637579 | N14: =$K14*C14 -> 0.47376953 | O14: =$K14*D14 -> 0.087001868 | P14: =$E14*LN(J14)+(1-$E14)*LN(1-J14) -> -0.69314718 | V14: =U$2+ U$3*$B14+U$4*$C14+U$5*$D14 -> -0.00029730246 | W14: =1/(1+EXP(-V14)) -> 0.49992567 | X14: =W14-$E14 -> -0.50007433 | Y14: =$X14*A14 -> -0.50007433 | Z14: =$X14*B14 -> 0.016640053 | AA14: =$X14*C14 -> 0.47383995 | AB14: =$X14*D14 -> 0.087014801 | AC14: =$E14*LN(W14)+(1-$E14)*LN(1-W14) -> -0.69329584 | AI14: =AH$2+ AH$3*$B14+AH$4*$C14+AH$5*$D14 -> -0.00059247595 | AJ14: =1/(1+EXP(-AI14)) -> 0.49985188 | AK14: =AJ14-$E14 -> -0.50014812 | AL14: =$AK14*A14 -> -0.50014812 | AM14: =$AK14*B14 -> 0.016642508 | AN14: =$AK14*C14 -> 0.47390988 | AO14: =$AK14*D14 -> 0.087027641 | AP14: =$E14*LN(AJ14)+(1-$E14)*LN(1-AJ14) -> -0.69344346
A15: 1 | B15: =('Data-LR-Short-Train'!A14-'Data-LR-Short-Train'!$F$10)/'Data-LR-Short-Train'!$G$10 -> 0.44208425 | C15: =('Data-LR-Short-Train'!B14-'Data-LR-Short-Train'!$F$13)/'Data-LR-Short-Train'!$G$13 -> -0.89355865 | D15: =('Data-LR-Short-Train'!C14-'Data-LR-Short-Train'!$F$16)/'Data-LR-Short-Train'!$G$16 -> -0.23878303 | E15: ='Data-LR-Short-Train'!D14 -> 0 | I15: =H$2+ H$3*$B15+H$4*$C15+H$5*$D15 -> 0 | J15: =1/(1+EXP(-I15)) -> 0.5 | K15: =J15-$E15 -> 0.5 | L15: =$K15*A15 -> 0.5 | M15: =$K15*B15 -> 0.22104213 | N15: =$K15*C15 -> -0.44677933 | O15: =$K15*D15 -> -0.11939152 | P15: =$E15*LN(J15)+(1-$E15)*LN(1-J15) -> -0.69314718 | V15: =U$2+ U$3*$B15+U$4*$C15+U$5*$D15 -> -0.00018324008 | W15: =1/(1+EXP(-V15)) -> 0.49995419 | X15: =W15-$E15 -> 0.49995419 | Y15: =$X15*A15 -> 0.49995419 | Z15: =$X15*B15 -> 0.22102188 | AA15: =$X15*C15 -> -0.44673839 | AB15: =$X15*D15 -> -0.11938058 | AC15: =$E15*LN(W15)+(1-$E15)*LN(1-W15) -> -0.69305556 | AI15: =AH$2+ AH$3*$B15+AH$4*$C15+AH$5*$D15 -> -0.00036476144 | AJ15: =1/(1+EXP(-AI15)) -> 0.49990881 | AK15: =AJ15-$E15 -> 0.49990881 | AL15: =$AK15*A15 -> 0.49990881 | AM15: =$AK15*B15 -> 0.22100181 | AN15: =$AK15*C15 -> -0.44669784 | AO15: =$AK15*D15 -> -0.11936974 | AP15: =$E15*LN(AJ15)+(1-$E15)*LN(1-AJ15) -> -0.69296482
A16: 1 | B16: =('Data-LR-Short-Train'!A15-'Data-LR-Short-Train'!$F$10)/'Data-LR-Short-Train'!$G$10 -> -0.60370646 | C16: =('Data-LR-Short-Train'!B15-'Data-LR-Short-Train'!$F$13)/'Data-LR-Short-Train'!$G$13 -> -1.1541913 | D16: =('Data-LR-Short-Train'!C15-'Data-LR-Short-Train'!$F$16)/'Data-LR-Short-Train'!$G$16 -> -0.71953638 | E16: ='Data-LR-Short-Train'!D15 -> 0 | I16: =H$2+ H$3*$B16+H$4*$C16+H$5*$D16 -> 0 | J16: =1/(1+EXP(-I16)) -> 0.5 | K16: =J16-$E16 -> 0.5 | L16: =$K16*A16 -> 0.5 | M16: =$K16*B16 -> -0.30185323 | N16: =$K16*C16 -> -0.57709565 | O16: =$K16*D16 -> -0.35976819 | P16: =$E16*LN(J16)+(1-$E16)*LN(1-J16) -> -0.69314718 | V16: =U$2+ U$3*$B16+U$4*$C16+U$5*$D16 -> -0.00093018432 | W16: =1/(1+EXP(-V16)) -> 0.49976745 | X16: =W16-$E16 -> 0.49976745 | Y16: =$X16*A16 -> 0.49976745 | Z16: =$X16*B16 -> -0.30171284 | AA16: =$X16*C16 -> -0.57682724 | AB16: =$X16*D16 -> -0.35960086 | AC16: =$E16*LN(W16)+(1-$E16)*LN(1-W16) -> -0.6926822 | AI16: =AH$2+ AH$3*$B16+AH$4*$C16+AH$5*$D16 -> -0.0018561366 | AJ16: =1/(1+EXP(-AI16)) -> 0.49953597 | AK16: =AJ16-$E16 -> 0.49953597 | AL16: =$AK16*A16 -> 0.49953597 | AM16: =$AK16*B16 -> -0.30157309 | AN16: =$AK16*C16 -> -0.57656006 | AO16: =$AK16*D16 -> -0.3594343 | AP16: =$E16*LN(AJ16)+(1-$E16)*LN(1-AJ16) -> -0.69221954
A17: 1 | B17: =('Data-LR-Short-Train'!A16-'Data-LR-Short-Train'!$F$10)/'Data-LR-Short-Train'!$G$10 -> -0.60370646 | C17: =('Data-LR-Short-Train'!B16-'Data-LR-Short-Train'!$F$13)/'Data-LR-Short-Train'!$G$13 -> -0.34906068 | D17: =('Data-LR-Short-Train'!C16-'Data-LR-Short-Train'!$F$16)/'Data-LR-Short-Train'!$G$16 -> -0.31047697 | E17: ='Data-LR-Short-Train'!D16 -> 0 | I17: =H$2+ H$3*$B17+H$4*$C17+H$5*$D17 -> 0 | J17: =1/(1+EXP(-I17)) -> 0.5 | K17: =J17-$E17 -> 0.5 | L17: =$K17*A17 -> 0.5 | M17: =$K17*B17 -> -0.30185323 | N17: =$K17*C17 -> -0.17453034 | O17: =$K17*D17 -> -0.15523848 | P17: =$E17*LN(J17)+(1-$E17)*LN(1-J17) -> -0.69314718 | V17: =U$2+ U$3*$B17+U$4*$C17+U$5*$D17 -> -0.00048856903 | W17: =1/(1+EXP(-V17)) -> 0.49987786 | X17: =W17-$E17 -> 0.49987786 | Y17: =$X17*A17 -> 0.49987786 | Z17: =$X17*B17 -> -0.30177949 | AA17: =$X17*C17 -> -0.1744877 | AB17: =$X17*D17 -> -0.15520056 | AC17: =$E17*LN(W17)+(1-$E17)*LN(1-W17) -> -0.69290293 | AI17: =AH$2+ AH$3*$B17+AH$4*$C17+AH$5*$D17 -> -0.00097525526 | AJ17: =1/(1+EXP(-AI17)) -> 0.49975619 | AK17: =AJ17-$E17 -> 0.49975619 | AL17: =$AK17*A17 -> 0.49975619 | AM17: =$AK17*B17 -> -0.30170604 | AN17: =$AK17*C17 -> -0.17444523 | AO17: =$AK17*D17 -> -0.15516279 | AP17: =$E17*LN(AJ17)+(1-$E17)*LN(1-AJ17) -> -0.69265967
A18: 1 | B18: =('Data-LR-Short-Train'!A17-'Data-LR-Short-Train'!$F$10)/'Data-LR-Short-Train'!$G$10 -> 0.67976396 | C18: =('Data-LR-Short-Train'!B17-'Data-LR-Short-Train'!$F$13)/'Data-LR-Short-Train'!$G$13 -> 0.7337158 | D18: =('Data-LR-Short-Train'!C17-'Data-LR-Short-Train'!$F$16)/'Data-LR-Short-Train'!$G$16 -> 0.025429149 | E18: ='Data-LR-Short-Train'!D17 -> 1 | I18: =H$2+ H$3*$B18+H$4*$C18+H$5*$D18 -> 0 | J18: =1/(1+EXP(-I18)) -> 0.5 | K18: =J18-$E18 -> -0.5 | L18: =$K18*A18 -> -0.5 | M18: =$K18*B18 -> -0.33988198 | N18: =$K18*C18 -> -0.3668579 | O18: =$K18*D18 -> -0.012714574 | P18: =$E18*LN(J18)+(1-$E18)*LN(1-J18) -> -0.69314718 | V18: =U$2+ U$3*$B18+U$4*$C18+U$5*$D18 -> 0.00035971694 | W18: =1/(1+EXP(-V18)) -> 0.50008993 | X18: =W18-$E18 -> -0.49991007 | Y18: =$X18*A18 -> -0.49991007 | Z18: =$X18*B18 -> -0.33982085 | AA18: =$X18*C18 -> -0.36679192 | AB18: =$X18*D18 -> -0.012712287 | AC18: =$E18*LN(W18)+(1-$E18)*LN(1-W18) -> -0.69296734 | AI18: =AH$2+ AH$3*$B18+AH$4*$C18+AH$5*$D18 -> 0.0007173995 | AJ18: =1/(1+EXP(-AI18)) -> 0.50017935 | AK18: =AJ18-$E18 -> -0.49982065 | AL18: =$AK18*A18 -> -0.49982065 | AM18: =$AK18*B18 -> -0.33976007 | AN18: =$AK18*C18 -> -0.36672631 | AO18: =$AK18*D18 -> -0.012710014 | AP18: =$E18*LN(AJ18)+(1-$E18)*LN(1-AJ18) -> -0.69278855
A19: 1 | B19: =('Data-LR-Short-Train'!A18-'Data-LR-Short-Train'!$F$10)/'Data-LR-Short-Train'!$G$10 -> -0.12834704 | C19: =('Data-LR-Short-Train'!B18-'Data-LR-Short-Train'!$F$13)/'Data-LR-Short-Train'!$G$13 -> 0.48646208 | D19: =('Data-LR-Short-Train'!C18-'Data-LR-Short-Train'!$F$16)/'Data-LR-Short-Train'!$G$16 -> -0.051359791 | E19: ='Data-LR-Short-Train'!D18 -> 0 | I19: =H$2+ H$3*$B19+H$4*$C19+H$5*$D19 -> 0 | J19: =1/(1+EXP(-I19)) -> 0.5 | K19: =J19-$E19 -> 0.5 | L19: =$K19*A19 -> 0.5 | M19: =$K19*B19 -> -0.064173521 | N19: =$K19*C19 -> 0.24323104 | O19: =$K19*D19 -> -0.025679895 | P19: =$E19*LN(J19)+(1-$E19)*LN(1-J19) -> -0.69314718 | V19: =U$2+ U$3*$B19+U$4*$C19+U$5*$D19 -> -1.3505758e-06 | W19: =1/(1+EXP(-V19)) -> 0.49999966 | X19: =W19-$E19 -> 0.49999966 | Y19: =$X19*A19 -> 0.49999966 | Z19: =$X19*B19 -> -0.064173477 | AA19: =$X19*C19 -> 0.24323088 | AB19: =$X19*D19 -> -0.025679878 | AC19: =$E19*LN(W19)+(1-$E19)*LN(1-W19) -> -0.69314651 | AI19: =AH$2+ AH$3*$B19+AH$4*$C19+AH$5*$D19 -> -3.3500994e-06 | AJ19: =1/(1+EXP(-AI19)) -> 0.49999916 | AK19: =AJ19-$E19 -> 0.49999916 | AL19: =$AK19*A19 -> 0.49999916 | AM19: =$AK19*B19 -> -0.064173413 | AN19: =$AK19*C19 -> 0.24323063 | AO19: =$AK19*D19 -> -0.025679852 | AP19: =$E19*LN(AJ19)+(1-$E19)*LN(1-AJ19) -> -0.69314551
A20: 1 | B20: =('Data-LR-Short-Train'!A19-'Data-LR-Short-Train'!$F$10)/'Data-LR-Short-Train'!$G$10 -> -0.50863457 | C20: =('Data-LR-Short-Train'!B19-'Data-LR-Short-Train'!$F$13)/'Data-LR-Short-Train'!$G$13 -> -0.20354829 | D20: =('Data-LR-Short-Train'!C19-'Data-LR-Short-Train'!$F$16)/'Data-LR-Short-Train'!$G$16 -> -0.28318232 | E20: ='Data-LR-Short-Train'!D19 -> 0 | I20: =H$2+ H$3*$B20+H$4*$C20+H$5*$D20 -> 0 | J20: =1/(1+EXP(-I20)) -> 0.5 | K20: =J20-$E20 -> 0.5 | L20: =$K20*A20 -> 0.5 | M20: =$K20*B20 -> -0.25431729 | N20: =$K20*C20 -> -0.10177414 | O20: =$K20*D20 -> -0.14159116 | P20: =$E20*LN(J20)+(1-$E20)*LN(1-J20) -> -0.69314718 | V20: =U$2+ U$3*$B20+U$4*$C20+U$5*$D20 -> -0.00041325563 | W20: =1/(1+EXP(-V20)) -> 0.49989669 | X20: =W20-$E20 -> 0.49989669 | Y20: =$X20*A20 -> 0.49989669 | Z20: =$X20*B20 -> -0.25426474 | AA20: =$X20*C20 -> -0.10175311 | AB20: =$X20*D20 -> -0.1415619 | AC20: =$E20*LN(W20)+(1-$E20)*LN(1-W20) -> -0.69294057 | AI20: =AH$2+ AH$3*$B20+AH$4*$C20+AH$5*$D20 -> -0.00082504236 | AJ20: =1/(1+EXP(-AI20)) -> 0.49979374 | AK20: =AJ20-$E20 -> 0.49979374 | AL20: =$AK20*A20 -> 0.49979374 | AM20: =$AK20*B20 -> -0.25421237 | AN20: =$AK20*C20 -> -0.10173216 | AO20: =$AK20*D20 -> -0.14153275 | AP20: =$E20*LN(AJ20)+(1-$E20)*LN(1-AJ20) -> -0.69273474
A21: 1 | B21: =('Data-LR-Short-Train'!A20-'Data-LR-Short-Train'!$F$10)/'Data-LR-Short-Train'!$G$10 -> -0.27095487 | C21: =('Data-LR-Short-Train'!B20-'Data-LR-Short-Train'!$F$13)/'Data-LR-Short-Train'!$G$13 -> 2.071843 | D21: =('Data-LR-Short-Train'!C20-'Data-LR-Short-Train'!$F$16)/'Data-LR-Short-Train'!$G$16 -> 5.0811256 | E21: ='Data-LR-Short-Train'!D20 -> 1 | I21: =H$2+ H$3*$B21+H$4*$C21+H$5*$D21 -> 0 | J21: =1/(1+EXP(-I21)) -> 0.5 | K21: =J21-$E21 -> -0.5 | L21: =$K21*A21 -> -0.5 | M21: =$K21*B21 -> 0.13547743 | N21: =$K21*C21 -> -1.0359215 | O21: =$K21*D21 -> -2.5405628 | P21: =$E21*LN(J21)+(1-$E21)*LN(1-J21) -> -0.69314718 | V21: =U$2+ U$3*$B21+U$4*$C21+U$5*$D21 -> 0.0041048376 | W21: =1/(1+EXP(-V21)) -> 0.50102621 | X21: =W21-$E21 -> -0.49897379 | Y21: =$X21*A21 -> -0.49897379 | Z21: =$X21*B21 -> 0.13519938 | AA21: =$X21*C21 -> -1.0337954 | AB21: =$X21*D21 -> -2.5353485 | AC21: =$E21*LN(W21)+(1-$E21)*LN(1-W21) -> -0.69109687 | AI21: =AH$2+ AH$3*$B21+AH$4*$C21+AH$5*$D21 -> 0.0081951412 | AJ21: =1/(1+EXP(-AI21)) -> 0.50204877 | AK21: =AJ21-$E21 -> -0.49795123 | AL21: =$AK21*A21 -> -0.49795123 | AM21: =$AK21*B21 -> 0.13492231 | AN21: =$AK21*C21 -> -1.0316768 | AO21: =$AK21*D21 -> -2.5301527 | AP21: =$E21*LN(AJ21)+(1-$E21)*LN(1-AJ21) -> -0.689058
... A32: 1 | B32: =('Data-LR-Short-Train'!A31-'Data-LR-Short-Train'!$F$10)/'Data-LR-Short-Train'!$G$10 -> -0.84138616 | C32: =('Data-LR-Short-Train'!B31-'Data-LR-Short-Train'!$F$13)/'Data-LR-Short-Train'!$G$13 -> 0.62845401 | D32: =('Data-LR-Short-Train'!C31-'Data-LR-Short-Train'!$F$16)/'Data-LR-Short-Train'!$G$16 -> 0.73581782 | E32: ='Data-LR-Short-Train'!D31 -> 0 | I32: =H$2+ H$3*$B32+H$4*$C32+H$5*$D32 -> 0 | J32: =1/(1+EXP(-I32)) -> 0.5 | K32: =J32-$E32 -> 0.5 | L32: =$K32*A32 -> 0.5 | M32: =$K32*B32 -> -0.42069308 | N32: =$K32*C32 -> 0.31422701 | O32: =$K32*D32 -> 0.36790891 | P32: =$E32*LN(J32)+(1-$E32)*LN(1-J32) -> -0.69314718 | V32: =U$2+ U$3*$B32+U$4*$C32+U$5*$D32 -> 0.00038741902 | W32: =1/(1+EXP(-V32)) -> 0.50009685 | X32: =W32-$E32 -> 0.50009685 | Y32: =$X32*A32 -> 0.50009685 | Z32: =$X32*B32 -> -0.42077457 | AA32: =$X32*C32 -> 0.31428787 | AB32: =$X32*D32 -> 0.36798018 | AC32: =$E32*LN(W32)+(1-$E32)*LN(1-W32) -> -0.69334091 | AI32: =AH$2+ AH$3*$B32+AH$4*$C32+AH$5*$D32 -> 0.0007729017 | AJ32: =1/(1+EXP(-AI32)) -> 0.50019323 | AK32: =AJ32-$E32 -> 0.50019323 | AL32: =$AK32*A32 -> 0.50019323 | AM32: =$AK32*B32 -> -0.42085566 | AN32: =$AK32*C32 -> 0.31434844 | AO32: =$AK32*D32 -> 0.36805109 | AP32: =$E32*LN(AJ32)+(1-$E32)*LN(1-AJ32) -> -0.69353371
B34: Các tham số chạy Gradient Descent để tìm các hệ số hồi quy
B35: Input | C35: Value | D35: Desc
B36: n | C36: =COUNT(A3:A32) -> 30 | D36: số mẫu training
B37: ε | C37: 0.001 | D37: sai số, làm điều kiện dừng
B38: α = η | C38: 0.01 | D38: learning rate, bước nhảy
B39: Điều kiện dừng:
B40: Khi '‖𝓛(β)‖ < = ε HOẶC đạt số lần lặp max
B42: Iteration 1
B43: Output | C43: Value | D43: Desc
B44: ϐ0 | C44: =H2 -> 0 | D44: Hệ số hồi quy khởi tạo
B45: ϐ1 | C45: =H3 -> 0
B46: ϐ2 | C46: =H4 -> 0
B47: ϐ3 | C47: =H5 -> 0
B48: ‖𝓛(β)‖ | C48: =R8 -> 0.084126533 | D48: Xét điều kiện dừng
B49: 𝓛(β) | C49: =R9 -> 0.69314718 | D49: Quan sát hàm mất mát
B51: Iteration 2
B52: Output | C52: Value | D52: Desc
B53: ϐ0 | C53: =U2 -> 0
...

Sheet Data-LR-Short-Test
A1: Before Scale | E1: After Scale
A2: income | B2: amount | C2: down_payment | D2: label_refused | E2: income | F2: amount | G2: down_payment | H2: label_refused | I2: z | J2: ŷ | K2: lable_ŷ | L2: check
A3: 112500 | B3: 34473.6 | C3: 3451.5 | D3: 0 | E3: =(A3-'Data-LR-Short-Train'!$F$10)/'Data-LR-Short-Train'!$G$10 -> -0.74631428 | F3: =(B3-'Data-LR-Short-Train'!$F$13)/'Data-LR-Short-Train'!$G$13 -> -0.77024864 | G3: =(C3-'Data-LR-Short-Train'!$F$16)/'Data-LR-Short-Train'!$G$16 -> -0.44076342 | H3: =D3 -> 0 | I3: =$K$14+$K$15*E$3+$K$16*F$3+$K$17*G3 -> -0.0020980364 | J3: =1/(1+EXP(-I3)) -> 0.49947549 | K3: =IF(J3>=0.5,1,0) -> 0 | L3: =IF(H3-K3=0,"T","F") -> T
A4: 112500 | B4: 315000 | C4: 90000 | D4: 1 | E4: =(A4-'Data-LR-Short-Train'!$F$10)/'Data-LR-Short-Train'!$G$10 -> -0.74631428 | F4: =(B4-'Data-LR-Short-Train'!$F$13)/'Data-LR-Short-Train'!$G$13 -> 6.5451756 | G4: =(C4-'Data-LR-Short-Train'!$F$16)/'Data-LR-Short-Train'!$G$16 -> 6.5586758 | H4: =D4 -> 1 | I4: =$K$14+$K$15*E$3+$K$16*F$3+$K$17*G4 -> 0.013787985 | J4: =1/(1+EXP(-I4)) -> 0.50344694 | K4: =IF(J4>=0.5,1,0) -> 1 | L4: =IF(H4-K4=0,"T","F") -> T
A5: 252000 | B5: 38686.5 | C5: 3870 | D5: 1 | E5: =(A5-'Data-LR-Short-Train'!$F$10)/'Data-LR-Short-Train'!$G$10 -> 0.7272999 | F5: =(B5-'Data-LR-Short-Train'!$F$13)/'Data-LR-Short-Train'!$G$13 -> -0.66038678 | G5: =(C5-'Data-LR-Short-Train'!$F$16)/'Data-LR-Short-Train'!$G$16 -> -0.40691805 | H5: =D5 -> 1 | I5: =$K$14+$K$15*E$3+$K$16*F$3+$K$17*G5 -> -0.0020212205 | J5: =1/(1+EXP(-I5)) -> 0.4994947 | K5: =IF(J5>=0.5,1,0) -> 0 | L5: =IF(H5-K5=0,"T","F") -> F
A6: 202500 | B6: 59535 | C6: 6750 | D6: 0 | E6: =(A6-'Data-LR-Short-Train'!$F$10)/'Data-LR-Short-Train'!$G$10 -> 0.20440455 | F6: =(B6-'Data-LR-Short-Train'!$F$13)/'Data-LR-Short-Train'!$G$13 -> -0.11671025 | G6: =(C6-'Data-LR-Short-Train'!$F$16)/'Data-LR-Short-Train'!$G$16 -> -0.17400374 | H6: =D6 -> 0 | I6: =$K$14+$K$15*E$3+$K$16*F$3+$K$17*G6 -> -0.0014925951 | J6: =1/(1+EXP(-I6)) -> 0.49962685 | K6: =IF(J6>=0.5,1,0) -> 0 | L6: =IF(H6-K6=0,"T","F") -> T
A7: 202500 | B7: 31005 | C7: 6300 | D7: 0 | E7: =(A7-'Data-LR-Short-Train'!$F$10)/'Data-LR-Short-Train'!$G$10 -> 0.20440455 | F7: =(B7-'Data-LR-Short-Train'!$F$13)/'Data-LR-Short-Train'!$G$13 -> -0.86070102 | G7: =(C7-'Data-LR-Short-Train'!$F$16)/'Data-LR-Short-Train'!$G$16 -> -0.2103966 | H7: =D7 -> 0 | I7: =$K$14+$K$15*E$3+$K$16*F$3+$K$17*G7 -> -0.0015751928 | J7: =1/(1+EXP(-I7)) -> 0.4996062 | K7: =IF(J7>=0.5,1,0) -> 0 | L7: =IF(H7-K7=0,"T","F") -> T
A8: 202500 | B8: 49495.5 | C8: 9900 | D8: 0 | E8: =(A8-'Data-LR-Short-Train'!$F$10)/'Data-LR-Short-Train'!$G$10 -> 0.20440455 | F8: =(B8-'Data-LR-Short-Train'!$F$13)/'Data-LR-Short-Train'!$G$13 -> -0.3785152 | G8: =(C8-'Data-LR-Short-Train'!$F$16)/'Data-LR-Short-Train'!$G$16 -> 0.080746299 | H8: =D8 -> 0 | I8: =$K$14+$K$15*E$3+$K$16*F$3+$K$17*G8 -> -0.00091441097 | J8: =1/(1+EXP(-I8)) -> 0.4997714 | K8: =IF(J8>=0.5,1,0) -> 0 | L8: =IF(H8-K8=0,"T","F") -> T
A9: 180000 | B9: 71923.5 | C9: 7195.5 | D9: 0 | E9: =(A9-'Data-LR-Short-Train'!$F$10)/'Data-LR-Short-Train'!$G$10 -> -0.033275159 | F9: =(B9-'Data-LR-Short-Train'!$F$13)/'Data-LR-Short-Train'!$G$13 -> 0.20635073 | G9: =(C9-'Data-LR-Short-Train'!$F$16)/'Data-LR-Short-Train'!$G$16 -> -0.1379748 | H9: =D9 -> 0 | I9: =$K$14+$K$15*E$3+$K$16*F$3+$K$17*G9 -> -0.0014108233 | J9: =1/(1+EXP(-I9)) -> 0.49964729 | K9: =IF(J9>=0.5,1,0) -> 0 | L9: =IF(H9-K9=0,"T","F") -> T
A10: 121500 | B10: 108000 | C10: 10800 | D10: 1 | E10: =(A10-'Data-LR-Short-Train'!$F$10)/'Data-LR-Short-Train'!$G$10 -> -0.6512424 | F10: =(B10-'Data-LR-Short-Train'!$F$13)/'Data-LR-Short-Train'!$G$13 -> 1.1471353 | G10: =(C10-'Data-LR-Short-Train'!$F$16)/'Data-LR-Short-Train'!$G$16 -> 0.15353202 | H10: =D10 -> 1 | I10: =$K$14+$K$15*E$3+$K$16*F$3+$K$17*G10 -> -0.00074921551 | J10: =1/(1+EXP(-I10)) -> 0.4998127 | K10: =IF(J10>=0.5,1,0) -> 0 | L10: =IF(H10-K10=0,"T","F") -> F
A11: 202500 | B11: 62050.5 | C11: 22500 | D11: 1 | E11: =(A11-'Data-LR-Short-Train'!$F$10)/'Data-LR-Short-Train'!$G$10 -> 0.20440455 | F11: =(B11-'Data-LR-Short-Train'!$F$13)/'Data-LR-Short-Train'!$G$13 -> -0.051112322 | G11: =(C11-'Data-LR-Short-Train'!$F$16)/'Data-LR-Short-Train'!$G$16 -> 1.0997464 | H11: =D11 -> 1 | I11: =$K$14+$K$15*E$3+$K$16*F$3+$K$17*G11 -> 0.0013983254 | J11: =1/(1+EXP(-I11)) -> 0.50034958 | K11: =IF(J11>=0.5,1,0) -> 1 | L11: =IF(H11-K11=0,"T","F") -> T
A12: 225000 | B12: 22126.5 | C12: 4500 | D12: 1 | E12: =(A12-'Data-LR-Short-Train'!$F$10)/'Data-LR-Short-Train'!$G$10 -> 0.44208425 | F12: =(B12-'Data-LR-Short-Train'!$F$13)/'Data-LR-Short-Train'!$G$13 -> -1.09223 | G12: =(C12-'Data-LR-Short-Train'!$F$16)/'Data-LR-Short-Train'!$G$16 -> -0.35596805 | H12: =D12 -> 1 | I12: =$K$14+$K$15*E$3+$K$16*F$3+$K$17*G12 -> -0.0019055837 | J12: =1/(1+EXP(-I12)) -> 0.4995236 | K12: =IF(J12>=0.5,1,0) -> 0 | L12: =IF(H12-K12=0,"T","F") -> F
E14: mean và variance của income | H14: Sale X với mean và variance | J14: ϐ0 | K14: ='Logistic-Regression'!AH2-('Logistic-Regression'!$AR$6*'Logistic-Regression'!AR2) -> 4.5705371e-12
E15: μ1 | F15: σ1 | J15: ϐ1 | K15: ='Logistic-Regression'!AH3-('Logistic-Regression'!$AR$6*'Logistic-Regression'!AR3) -> 0.00097163181
E16: ='Data-LR-Short-Train'!F10 -> 183150 | F16: ='Data-LR-Short-Train'!G10 -> 94665.213 | J16: ϐ2 | K16: ='Logistic-Regression'!AH4-('Logistic-Regression'!$AR$6*'Logistic-Regression'!AR4) -> 0.00048365053
E17: mean và variance của amount | J17: ϐ3 | K17: ='Logistic-Regression'!AH5-('Logistic-Regression'!$AR$6*'Logistic-Regression'!AR5) -> 0.0022696134
E18: ='Data-LR-Short-Train'!F12 -> μ2 | F18: ='Data-LR-Short-Train'!G12 -> σ2
E19: ='Data-LR-Short-Train'!F13 -> 64010.517 | F19: ='Data-LR-Short-Train'!G13 -> 38347.25
E20: mean và variance của downpayment
E21: ='Data-LR-Short-Train'!F15 -> μ3 | F21: ='Data-LR-Short-Train'!G15 -> σ3
E22: ='Data-LR-Short-Train'!F16 -> 8901.567 | F22: ='Data-LR-Short-Train'!G16 -> 12365.062
